Workbook

Sheet LEEME
A1: Control de inventarios IMMEX — Anexo 24: representación en Excel para el desarrollo del sistema
A2: Empresa, pedimentos, precios y cantidades son ficticios. Los plazos, la multa y la estructura de reportes sí vienen de normas (ver fuentes abajo). Orden sugerido de lectura: este LEEME → Parametros → Catalogos → Entradas (la cédula) → Consumo → Salidas → Tablero → Reportes → Modelo_Datos.
A4: CÓMO FUNCIONA LA CÉDULA DE INVENTARIO
A5: 1. Cada pedimento de importación temporal de un material es un lote (un renglón en la hoja Entradas). Al entrar, empieza a correr su reloj legal: fecha de entrada + plazo (18 meses para insumos).
A6: 2. La producción del mes, multiplicada por la lista de materiales (BOM) y aumentada por la merma, da el consumo real de cada material (hoja Consumo).
A7: 3. Lo que debe descargarse de un material = consumo real + sus salidas (retornos, destrucciones, cambios de régimen).
A8: 4. Descarga PEPS: se descarga del pedimento más antiguo; si no alcanza, lo que falta se descarga del siguiente en orden cronológico. Saldo del lote = importado − descargado.
A9: 5. Cada lote con saldo muestra su vencimiento, días restantes, alerta (90/60/30) y su valor en pesos (saldo × valor unitario × tipo de cambio). Eso es el riesgo.
A10: 6. Conciliación: si lo que debe descargarse supera lo importado de un material, hay un FALTANTE. Es una excepción que alguien debe explicar (error de captura, pedimento sin registrar, retorno de más).
A11: 7. Los cuatro reportes del apartado A del Anexo 24 se arman a partir de estas hojas (hoja Reportes), con razón social y RFC en el encabezado.
A13: FUENTES LEGALES (qué se verificó y qué no)
A14: Fuente | B14: Qué establece | C14: Dónde se usa en este Excel | D14: Verificación
A15: Ley Aduanera, art. 108 (última reforma DOF 19-11-2025) | B15: Plazos de permanencia de la importación temporal de maquiladoras / IMMEX: hasta 18 meses para lubricantes y materiales que se consumen en el proceso, materias primas, partes y componentes que se integran totalmente a la exportación, envases y empaques, etiquetas y folletos; hasta 2 años para contenedores y cajas de trailers; por la vigencia del programa para maquinaria, equipo, herramientas, moldes, refacciones y demás activos. Si no se retornan o cambian de régimen en el plazo, se entienden ilegalmente en el país. Al notificarse la cancelación de un programa hay 60 días naturales para cambiar a importación definitiva o retornar. | C15: Catalogos (plazo_meses, fundamento), reloj legal en Entradas, Parametros (60 días). | D15: Texto oficial (captura de la Cámara de Diputados proporcionada por el usuario).
A16: Ley Aduanera, art. 185-B | B16: Multa de $27,070 a $54,180 MXN a quien cometa la infracción de no llevar los sistemas de control de inventarios del art. 185-A. El monto se actualiza cada año. | C16: Parametros (multa mín/máx), Tablero (referencia). | D16: Texto oficial (captura de la Cámara de Diputados). Confirmar monto vigente cada año.
A17: Anexo 24 de las RGCE para 2026 (DOF 15-01-2026) | B17: Información mínima del sistema automatizado de control de inventarios. Apartado A (regla 4.3.1): catálogos, módulo de aduanas, reportes, descarga PEPS. Apartado B: SECIIT (interfaces con sistema corporativo, conciliación, 24 horas). Apartado C: empresas certificadas (actualización en 48 horas, acceso en línea a la autoridad). | C17: Estructura de hojas, reportes, PEPS, razón social y RFC en reportes. | D17: Texto oficial (PDF proporcionado). Este Excel cubre el apartado A; B y C son la siguiente etapa.
A18: Decreto IMMEX y guía de la Secretaría de Economía (documento proporcionado, sin fecha) | B18: El titular del programa debe llevar un control de inventarios automatizado con la información mínima del Anexo IV del Decreto IMMEX (hoy desarrollada en el Anexo 24 de las RGCE). Informes a la SE (p. ej. reporte anual y reportes para mercancías sensibles) piden volumen y % de mermas y desperdicios. | C18: Fundamento general de la obligación; merma como dato a registrar. | D18: Guía secundaria. Revisar el Decreto vigente en el DOF antes de citarlo.
A19: MERMA: no existe porcentaje máximo en las fuentes revisadas | B19: Ni el art. 108, ni el art. 185-B, ni el Anexo 24 fijan un % máximo de merma. El Anexo 24 solo exige registrar mermas y desperdicios y descargar el desperdicio por PEPS al destruirlo, donarlo, transferirlo, retornarlo o cambiarlo de régimen. Destruir desperdicio requiere aviso previo (fuentes secundarias citan RGCE regla 4.3.5, ficha 102/LA y art. 109 de la LA, con 30 días hábiles de anticipación) y acta de hechos. | C19: Parametros (tolerancia 3% = supuesto interno), Consumo (columna Revisión), Salidas (destrucciones). | D19: Aviso de destrucción: fuente secundaria. Verificar en las RGCE 2026 y la ficha 102/LA.
A20: Alertas a 90 / 60 / 30 días | B20: Vienen del planteamiento del reto, no de una norma. | C20: Parametros, columna Alerta en Entradas, ventanas del Tablero. | D20: —
A22: EXCEPCIONES PLANTADAS A PROPÓSITO (fecha de corte 20/10/2026)
A23: • Resina ABS: el pedimento más antiguo vence en 16 días y aún tiene 827 kg de saldo (alerta 30).
A24: • Polipropileno: un pedimento vence en 40 días con 557 kg de saldo (alerta 60) y otro, con 15,000 kg íntegros, en 80 días (alerta 90).
A25: • Carcasa PT-002 en septiembre: merma de 5.8% contra la tolerancia interna de 3%.
A26: • Masterbatch: se retornaron 2,500 kg y solo se importaron 2,900; consumo más salidas exceden lo importado por 332.8 kg (faltante).
A28: LIMITACIONES
A29: • Solo se modelan insumos con plazo de 18 meses. Activo fijo (vigencia del programa) y contenedores (2 años) quedan fuera, y no se modelan las contribuciones e infracciones por mercancía vencida.
A30: • Fracciones arancelarias y claves de pedimento son ilustrativas. Tipo de cambio (18.50) y tolerancia de merma (3%) son supuestos editables.
A31: • No se valida que un consumo sea posterior a la fecha de entrada del pedimento que descarga. Los rangos de fórmulas cubren hasta la fila 40 de cada hoja.
A32: • Esto es una representación contable-operativa de apoyo; no sustituye la opinión de un especialista aduanal ni la revisión del texto legal vigente.

Sheet Parametros
A1: Parámetros
A2: Azul con fondo amarillo = editable. Columna C: LEY = viene de una norma; RETO = viene del planteamiento del reto; SUPUESTO = valor de este ejercicio, no es norma.
A3: Parámetro | B3: Valor | C3: Tipo | D3: Fundamento / nota
A4: Razón social | B4: Plásticos Ejemplo, S.A. de C.V. | C4: SUPUESTO | D4: Empresa ficticia.
A5: RFC | B5: PEJ210101AB1 | C5: SUPUESTO | D5: Ficticio. Anexo 24 apdo. A, fr. I inc. a): razón social y RFC deben aparecer en todos los reportes.
A6: Programa IMMEX (No. SE) | B6: 0000-2024 | C6: SUPUESTO | D6: Ficticio.
A7: Domicilio fiscal / planta | B7: Parque Industrial Ejemplo, Nave 4, C.P. 00000, Monterrey, N.L. | C7: SUPUESTO | D7: Ficticio. El Anexo 24 pide domicilio fiscal y de plantas/bodegas.
A8: Fecha de corte | B8: 46315 | C8: SUPUESTO | D8: Fecha contra la que corre el reloj legal. Cámbiela para simular otros días.
A9: Tipo de cambio MXN por USD | B9: 18.5 | C9: SUPUESTO | D9: Para valuar el riesgo en pesos. Actualizar al tipo de cambio que corresponda.
A10: Tolerancia de merma (alerta interna) | B10: 0.03 | C10: SUPUESTO | D10: Ninguna fuente revisada fija un % máximo de merma (ver LEEME). Es un umbral interno para marcar excepciones.
A11: Alerta temprana (días) | B11: 90 | C11: RETO | D11: Planteamiento del reto: alertas a 90, 60 y 30 días antes del vencimiento. No es un plazo legal.
A12: Alerta intermedia (días) | B12: 60 | C12: RETO | D12: Ídem.
A13: Alerta crítica (días) | B13: 30 | C13: RETO | D13: Ídem.
A14: Multa mínima por no llevar control de inventarios (MXN) | B14: 27070 | C14: LEY | D14: Ley Aduanera art. 185-B (texto oficial, últ. reforma DOF 19-11-2025).
A15: Multa máxima (MXN) | B15: 54180 | C15: LEY | D15: Ídem. Se aplica a quien incumpla la obligación de llevar sistemas de control de inventarios (art. 185-A). Monto actualizado cada año.
A16: Plazo para cambiar de régimen tras cancelación del programa (días naturales) | B16: 60 | C16: LEY | D16: Ley Aduanera art. 108, párrafo adicionado DOF 19-11-2025: desde que se notifica la cancelación.

Sheet Catalogos
A1: Catálogos (Anexo 24, apdo. A, fr. I: materiales y productos; más la lista de materiales o BOM)
A3: Materiales | H3: Lista de materiales (BOM): kg de material por pieza
A4: Clave | B4: Descripción comercial | C4: Fracción arancelaria | D4: UM TIGIE | E4: Plazo legal (meses) | F4: Fundamento del plazo | H4: Producto | I4: Material | J4: kg por pieza
A5: MP-001 | B5: Resina polipropileno copolímero | C5: 3902.10.01 | D5: KGM | E5: 18 | F5: LA art. 108 fr. I inc. b): materias primas, partes y componentes destinados a integrar mercancía de exportación | H5: PT-001 | I5: MP-001 | J5: 0.028
A6: MP-002 | B6: Resina ABS | C6: 3903.30.01 | D6: KGM | E6: 18 | F6: LA art. 108 fr. I inc. b) | H6: PT-001 | I6: MP-003 | J6: 0.0006
A7: MP-003 | B7: Masterbatch colorante | C7: 3206.49.99 | D7: KGM | E7: 18 | F7: LA art. 108 fr. I inc. b) | H7: PT-002 | I7: MP-002 | J7: 0.085
H8: PT-002 | I8: MP-003 | J8: 0.0017
A9: Otros plazos del art. 108 (no modelados): envases, empaques, etiquetas, folletos y lubricantes = 18 meses; contenedores y cajas de trailers = 2 años; maquinaria, equipo, moldes y refacciones = vigencia del programa.
A11: Productos terminados
A12: Clave | B12: Descripción comercial | C12: Fracción arancelaria | D12: UM TIGIE
A13: PT-001 | B13: Tapa rosca 38 mm | C13: 3923.50.01 | D13: PZA
A14: PT-002 | B14: Carcasa control remoto | C14: 3926.90.99 | D14: PZA
A16: Fracciones arancelarias ilustrativas: validar contra la TIGIE antes de usar con una empresa real.

Sheet Entradas
A1: Cédula de inventario por pedimento (ledger): un renglón = un pedimento de importación temporal de un material
A2: Azul = captura. Negro = fórmula. Fila 3 explica cómo se calcula cada columna.
A3: Dato del pedimento | C3: Dato del pedimento | D3: Clave de catálogo | E3: Lookup en Catalogos | F3: Lookup en Catalogos | G3: Dato del pedimento | H3: Valor en USD / kg | I3: Cálculo: MIN(importado, MAX(0, total a descargar del material − importado de pedimentos MÁS ANTIGUOS del mismo material)) | J3: Cálculo: importado − descargado | K3: Cálculo: fecha de entrada + plazo legal del material (Catalogos) | L3: Cálculo: vence − fecha de corte | M3: Agotado / VENCIDO / ALERTA 30-60-90 / OK según días restantes | N3: Cálculo: saldo × valor unitario × tipo de cambio
A4: Pedimento (aduana-patente-número) | B4: Clave | C4: Fecha de entrada | D4: Material | E4: Descripción | F4: Fracción | G4: Cantidad importada (kg) | H4: Valor unitario (USD/kg) | I4: Descargado PEPS (kg) | J4: Saldo (kg) | K4: Vence (reloj legal) | L4: Días restantes | M4: Alerta | N4: Valor del saldo (MXN)
A5: 240-3210-6000101 | B5: IN | C5: 45806 | D5: MP-001 | E5: =IFERROR(INDEX(Catalogos!$B$5:$B$9,MATCH(D5,Catalogos!$A$5:$A$9,0)),"") -> Resina polipropileno copolímero | F5: =IFERROR(INDEX(Catalogos!$C$5:$C$9,MATCH(D5,Catalogos!$A$5:$A$9,0)),"") -> 3902.10.01 | G5: 24500 | H5: 1.35 | I5: =MIN(G5,MAX(0,SUMIFS(Consumo!$I$14:$I$40,Consumo!$C$14:$C$40,D5)+SUMIFS(Salidas!$F$5:$F$40,Salidas!$D$5:$D$40,D5)-SUMIFS($G$5:$G$40,$D$5:$D$40,D5,$C$5:$C$40,"<"&C5))) -> 23942.72 | J5: =G5-I5 -> 557.28 | K5: =EDATE(C5,INDEX(Catalogos!$E$5:$E$9,MATCH(D5,Catalogos!$A$5:$A$9,0))) -> 46355 | L5: =K5-Parametros!$B$8 -> 40 | M5: =IF(ROUND(J5,3)<=0,"Agotado",IF(L5<0,"VENCIDO",IF(L5<=Parametros!$B$13,"ALERTA 30",IF(L5<=Parametros!$B$12,"ALERTA 60",IF(L5<=Parametros!$B$11,"ALERTA 90","OK"))))) -> ALERTA 60 | N5: =J5*H5*Parametros!$B$9 -> 13918.068
A6: 240-3210-6000140 | B6: IN | C6: 45846 | D6: MP-001 | E6: =IFERROR(INDEX(Catalogos!$B$5:$B$9,MATCH(D6,Catalogos!$A$5:$A$9,0)),"") -> Resina polipropileno copolímero | F6: =IFERROR(INDEX(Catalogos!$C$5:$C$9,MATCH(D6,Catalogos!$A$5:$A$9,0)),"") -> 3902.10.01 | G6: 15000 | H6: 1.38 | I6: =MIN(G6,MAX(0,SUMIFS(Consumo!$I$14:$I$40,Consumo!$C$14:$C$40,D6)+SUMIFS(Salidas!$F$5:$F$40,Salidas!$D$5:$D$40,D6)-SUMIFS($G$5:$G$40,$D$5:$D$40,D6,$C$5:$C$40,"<"&C6))) -> 0 | J6: =G6-I6 -> 15000 | K6: =EDATE(C6,INDEX(Catalogos!$E$5:$E$9,MATCH(D6,Catalogos!$A$5:$A$9,0))) -> 46395 | L6: =K6-Parametros!$B$8 -> 80 | M6: =IF(ROUND(J6,3)<=0,"Agotado",IF(L6<0,"VENCIDO",IF(L6<=Parametros!$B$13,"ALERTA 30",IF(L6<=Parametros!$B$12,"ALERTA 60",IF(L6<=Parametros!$B$11,"ALERTA 90","OK"))))) -> ALERTA 90 | N6: =J6*H6*Parametros!$B$9 -> 382950
A7: 240-3210-6000377 | B7: IN | C7: 46091 | D7: MP-001 | E7: =IFERROR(INDEX(Catalogos!$B$5:$B$9,MATCH(D7,Catalogos!$A$5:$A$9,0)),"") -> Resina polipropileno copolímero | F7: =IFERROR(INDEX(Catalogos!$C$5:$C$9,MATCH(D7,Catalogos!$A$5:$A$9,0)),"") -> 3902.10.01 | G7: 10000 | H7: 1.42 | I7: =MIN(G7,MAX(0,SUMIFS(Consumo!$I$14:$I$40,Consumo!$C$14:$C$40,D7)+SUMIFS(Salidas!$F$5:$F$40,Salidas!$D$5:$D$40,D7)-SUMIFS($G$5:$G$40,$D$5:$D$40,D7,$C$5:$C$40,"<"&C7))) -> 0 | J7: =G7-I7 -> 10000 | K7: =EDATE(C7,INDEX(Catalogos!$E$5:$E$9,MATCH(D7,Catalogos!$A$5:$A$9,0))) -> 46640 | L7: =K7-Parametros!$B$8 -> 325 | M7: =IF(ROUND(J7,3)<=0,"Agotado",IF(L7<0,"VENCIDO",IF(L7<=Parametros!$B$13,"ALERTA 30",IF(L7<=Parametros!$B$12,"ALERTA 60",IF(L7<=Parametros!$B$11,"ALERTA 90","OK"))))) -> OK | N7: =J7*H7*Parametros!$B$9 -> 262700
A8: 240-3210-6000590 | B8: IN | C8: 46254 | D8: MP-001 | E8: =IFERROR(INDEX(Catalogos!$B$5:$B$9,MATCH(D8,Catalogos!$A$5:$A$9,0)),"") -> Resina polipropileno copolímero | F8: =IFERROR(INDEX(Catalogos!$C$5:$C$9,MATCH(D8,Catalogos!$A$5:$A$9,0)),"") -> 3902.10.01 | G8: 12000 | H8: 1.4 | I8: =MIN(G8,MAX(0,SUMIFS(Consumo!$I$14:$I$40,Consumo!$C$14:$C$40,D8)+SUMIFS(Salidas!$F$5:$F$40,Salidas!$D$5:$D$40,D8)-SUMIFS($G$5:$G$40,$D$5:$D$40,D8,$C$5:$C$40,"<"&C8))) -> 0 | J8: =G8-I8 -> 12000 | K8: =EDATE(C8,INDEX(Catalogos!$E$5:$E$9,MATCH(D8,Catalogos!$A$5:$A$9,0))) -> 46803 | L8: =K8-Parametros!$B$8 -> 488 | M8: =IF(ROUND(J8,3)<=0,"Agotado",IF(L8<0,"VENCIDO",IF(L8<=Parametros!$B$13,"ALERTA 30",IF(L8<=Parametros!$B$12,"ALERTA 60",IF(L8<=Parametros!$B$11,"ALERTA 90","OK"))))) -> OK | N8: =J8*H8*Parametros!$B$9 -> 310800
A9: 240-3210-6000088 | B9: IN | C9: 45782 | D9: MP-002 | E9: =IFERROR(INDEX(Catalogos!$B$5:$B$9,MATCH(D9,Catalogos!$A$5:$A$9,0)),"") -> Resina ABS | F9: =IFERROR(INDEX(Catalogos!$C$5:$C$9,MATCH(D9,Catalogos!$A$5:$A$9,0)),"") -> 3903.30.01 | G9: 12500 | H9: 1.85 | I9: =MIN(G9,MAX(0,SUMIFS(Consumo!$I$14:$I$40,Consumo!$C$14:$C$40,D9)+SUMIFS(Salidas!$F$5:$F$40,Salidas!$D$5:$D$40,D9)-SUMIFS($G$5:$G$40,$D$5:$D$40,D9,$C$5:$C$40,"<"&C9))) -> 11672.6 | J9: =G9-I9 -> 827.4 | K9: =EDATE(C9,INDEX(Catalogos!$E$5:$E$9,MATCH(D9,Catalogos!$A$5:$A$9,0))) -> 46331 | L9: =K9-Parametros!$B$8 -> 16 | M9: =IF(ROUND(J9,3)<=0,"Agotado",IF(L9<0,"VENCIDO",IF(L9<=Parametros!$B$13,"ALERTA 30",IF(L9<=Parametros!$B$12,"ALERTA 60",IF(L9<=Parametros!$B$11,"ALERTA 90","OK"))))) -> ALERTA 30 | N9: =J9*H9*Parametros!$B$9 -> 28317.765
A10: 240-3210-6000301 | B10: IN | C10: 45993 | D10: MP-002 | E10: =IFERROR(INDEX(Catalogos!$B$5:$B$9,MATCH(D10,Catalogos!$A$5:$A$9,0)),"") -> Resina ABS | F10: =IFERROR(INDEX(Catalogos!$C$5:$C$9,MATCH(D10,Catalogos!$A$5:$A$9,0)),"") -> 3903.30.01 | G10: 9000 | H10: 1.88 | I10: =MIN(G10,MAX(0,SUMIFS(Consumo!$I$14:$I$40,Consumo!$C$14:$C$40,D10)+SUMIFS(Salidas!$F$5:$F$40,Salidas!$D$5:$D$40,D10)-SUMIFS($G$5:$G$40,$D$5:$D$40,D10,$C$5:$C$40,"<"&C10))) -> 0 | J10: =G10-I10 -> 9000 | K10: =EDATE(C10,INDEX(Catalogos!$E$5:$E$9,MATCH(D10,Catalogos!$A$5:$A$9,0))) -> 46540 | L10: =K10-Parametros!$B$8 -> 225 | M10: =IF(ROUND(J10,3)<=0,"Agotado",IF(L10<0,"VENCIDO",IF(L10<=Parametros!$B$13,"ALERTA 30",IF(L10<=Parametros!$B$12,"ALERTA 60",IF(L10<=Parametros!$B$11,"ALERTA 90","OK"))))) -> OK | N10: =J10*H10*Parametros!$B$9 -> 313020
A11: 240-3210-6000544 | B11: IN | C11: 46217 | D11: MP-002 | E11: =IFERROR(INDEX(Catalogos!$B$5:$B$9,MATCH(D11,Catalogos!$A$5:$A$9,0)),"") -> Resina ABS | F11: =IFERROR(INDEX(Catalogos!$C$5:$C$9,MATCH(D11,Catalogos!$A$5:$A$9,0)),"") -> 3903.30.01 | G11: 8000 | H11: 1.9 | I11: =MIN(G11,MAX(0,SUMIFS(Consumo!$I$14:$I$40,Consumo!$C$14:$C$40,D11)+SUMIFS(Salidas!$F$5:$F$40,Salidas!$D$5:$D$40,D11)-SUMIFS($G$5:$G$40,$D$5:$D$40,D11,$C$5:$C$40,"<"&C11))) -> 0 | J11: =G11-I11 -> 8000 | K11: =EDATE(C11,INDEX(Catalogos!$E$5:$E$9,MATCH(D11,Catalogos!$A$5:$A$9,0))) -> 46766 | L11: =K11-Parametros!$B$8 -> 451 | M11: =IF(ROUND(J11,3)<=0,"Agotado",IF(L11<0,"VENCIDO",IF(L11<=Parametros!$B$13,"ALERTA 30",IF(L11<=Parametros!$B$12,"ALERTA 60",IF(L11<=Parametros!$B$11,"ALERTA 90","OK"))))) -> OK | N11: =J11*H11*Parametros!$B$9 -> 281200
A12: 240-3210-6000212 | B12: IN | C12: 45910 | D12: MP-003 | E12: =IFERROR(INDEX(Catalogos!$B$5:$B$9,MATCH(D12,Catalogos!$A$5:$A$9,0)),"") -> Masterbatch colorante | F12: =IFERROR(INDEX(Catalogos!$C$5:$C$9,MATCH(D12,Catalogos!$A$5:$A$9,0)),"") -> 3206.49.99 | G12: 900 | H12: 4.2 | I12: =MIN(G12,MAX(0,SUMIFS(Consumo!$I$14:$I$40,Consumo!$C$14:$C$40,D12)+SUMIFS(Salidas!$F$5:$F$40,Salidas!$D$5:$D$40,D12)-SUMIFS($G$5:$G$40,$D$5:$D$40,D12,$C$5:$C$40,"<"&C12))) -> 900 | J12: =G12-I12 -> 0 | K12: =EDATE(C12,INDEX(Catalogos!$E$5:$E$9,MATCH(D12,Catalogos!$A$5:$A$9,0))) -> 46456 | L12: =K12-Parametros!$B$8 -> 141 | M12: =IF(ROUND(J12,3)<=0,"Agotado",IF(L12<0,"VENCIDO",IF(L12<=Parametros!$B$13,"ALERTA 30",IF(L12<=Parametros!$B$12,"ALERTA 60",IF(L12<=Parametros!$B$11,"ALERTA 90","OK"))))) -> Agotado | N12: =J12*H12*Parametros!$B$9 -> 0
A13: 240-3210-6000350 | B13: IN | C13: 46042 | D13: MP-003 | E13: =IFERROR(INDEX(Catalogos!$B$5:$B$9,MATCH(D13,Catalogos!$A$5:$A$9,0)),"") -> Masterbatch colorante | F13: =IFERROR(INDEX(Catalogos!$C$5:$C$9,MATCH(D13,Catalogos!$A$5:$A$9,0)),"") -> 3206.49.99 | G13: 1200 | H13: 4.25 | I13: =MIN(G13,MAX(0,SUMIFS(Consumo!$I$14:$I$40,Consumo!$C$14:$C$40,D13)+SUMIFS(Salidas!$F$5:$F$40,Salidas!$D$5:$D$40,D13)-SUMIFS($G$5:$G$40,$D$5:$D$40,D13,$C$5:$C$40,"<"&C13))) -> 1200 | J13: =G13-I13 -> 0 | K13: =EDATE(C13,INDEX(Catalogos!$E$5:$E$9,MATCH(D13,Catalogos!$A$5:$A$9,0))) -> 46588 | L13: =K13-Parametros!$B$8 -> 273 | M13: =IF(ROUND(J13,3)<=0,"Agotado",IF(L13<0,"VENCIDO",IF(L13<=Parametros!$B$13,"ALERTA 30",IF(L13<=Parametros!$B$12,"ALERTA 60",IF(L13<=Parametros!$B$11,"ALERTA 90","OK"))))) -> Agotado | N13: =J13*H13*Parametros!$B$9 -> 0
A14: 240-3210-6000571 | B14: IN | C14: 46266 | D14: MP-003 | E14: =IFERROR(INDEX(Catalogos!$B$5:$B$9,MATCH(D14,Catalogos!$A$5:$A$9,0)),"") -> Masterbatch colorante | F14: =IFERROR(INDEX(Catalogos!$C$5:$C$9,MATCH(D14,Catalogos!$A$5:$A$9,0)),"") -> 3206.49.99 | G14: 800 | H14: 4.3 | I14: =MIN(G14,MAX(0,SUMIFS(Consumo!$I$14:$I$40,Consumo!$C$14:$C$40,D14)+SUMIFS(Salidas!$F$5:$F$40,Salidas!$D$5:$D$40,D14)-SUMIFS($G$5:$G$40,$D$5:$D$40,D14,$C$5:$C$40,"<"&C14))) -> 800 | J14: =G14-I14 -> 0 | K14: =EDATE(C14,INDEX(Catalogos!$E$5:$E$9,MATCH(D14,Catalogos!$A$5:$A$9,0))) -> 46813 | L14: =K14-Parametros!$B$8 -> 498 | M14: =IF(ROUND(J14,3)<=0,"Agotado",IF(L14<0,"VENCIDO",IF(L14<=Parametros!$B$13,"ALERTA 30",IF(L14<=Parametros!$B$12,"ALERTA 60",IF(L14<=Parametros!$B$11,"ALERTA 90","OK"))))) -> Agotado | N14: =J14*H14*Parametros!$B$9 -> 0

Sheet Consumo
A1: Producción y consumo real de materiales (Anexo 24, apdo. A, fr. II inc. b: módulo de materiales utilizados)
A3: A. Producción del periodo (captura mensual del cliente)
A4: Periodo | B4: Producto | C4: Piezas producidas | D4: Merma real (% del consumo teórico)
A5: 2026-08 | B5: PT-001 | C5: 400000 | D5: 0.02
A6: 2026-08 | B6: PT-002 | C6: 60000 | D6: 0.025
A7: 2026-09 | B7: PT-001 | C7: 420000 | D7: 0.022
A8: 2026-09 | B8: PT-002 | C8: 70000 | D8: 0.058
A11: B. Consumo real calculado = piezas × BOM + merma (fórmulas; no se captura)
A12: Consumo real = consumo teórico × (1 + merma %). Es lo que se descarga por PEPS en la cédula (hoja Entradas).
A13: Periodo | B13: Producto | C13: Material | D13: Piezas | E13: kg por pieza (BOM) | F13: Consumo teórico (kg) | G13: Merma % | H13: Merma (kg) | I13: Consumo real (kg) | J13: Revisión
A14: =A5 -> 2026-08 | B14: =B5 -> PT-001 | C14: =Catalogos!I5 -> MP-001 | D14: =C5 -> 400000 | E14: =Catalogos!J5 -> 0.028 | F14: =D14*E14 -> 11200 | G14: =D5 -> 0.02 | H14: =F14*G14 -> 224 | I14: =F14+H14 -> 11424 | J14: =IF(G14>Parametros!$B$10,"MERMA EXCEDE","OK") -> OK
A15: =A5 -> 2026-08 | B15: =B5 -> PT-001 | C15: =Catalogos!I6 -> MP-003 | D15: =C5 -> 400000 | E15: =Catalogos!J6 -> 0.0006 | F15: =D15*E15 -> 240 | G15: =D5 -> 0.02 | H15: =F15*G15 -> 4.8 | I15: =F15+H15 -> 244.8 | J15: =IF(G15>Parametros!$B$10,"MERMA EXCEDE","OK") -> OK
A16: =A6 -> 2026-08 | B16: =B6 -> PT-002 | C16: =Catalogos!I7 -> MP-002 | D16: =C6 -> 60000 | E16: =Catalogos!J7 -> 0.085 | F16: =D16*E16 -> 5100 | G16: =D6 -> 0.025 | H16: =F16*G16 -> 127.5 | I16: =F16+H16 -> 5227.5 | J16: =IF(G16>Parametros!$B$10,"MERMA EXCEDE","OK") -> OK
A17: =A6 -> 2026-08 | B17: =B6 -> PT-002 | C17: =Catalogos!I8 -> MP-003 | D17: =C6 -> 60000 | E17: =Catalogos!J8 -> 0.0017 | F17: =D17*E17 -> 102 | G17: =D6 -> 0.025 | H17: =F17*G17 -> 2.55 | I17: =F17+H17 -> 104.55 | J17: =IF(G17>Parametros!$B$10,"MERMA EXCEDE","OK") -> OK
A18: =A7 -> 2026-09 | B18: =B7 -> PT-001 | C18: =Catalogos!I5 -> MP-001 | D18: =C7 -> 420000 | E18: =Catalogos!J5 -> 0.028 | F18: =D18*E18 -> 11760 | G18: =D7 -> 0.022 | H18: =F18*G18 -> 258.72 | I18: =F18+H18 -> 12018.72 | J18: =IF(G18>Parametros!$B$10,"MERMA EXCEDE","OK") -> OK
A19: =A7 -> 2026-09 | B19: =B7 -> PT-001 | C19: =Catalogos!I6 -> MP-003 | D19: =C7 -> 420000 | E19: =Catalogos!J6 -> 0.0006 | F19: =D19*E19 -> 252 | G19: =D7 -> 0.022 | H19: =F19*G19 -> 5.544 | I19: =F19+H19 -> 257.544 | J19: =IF(G19>Parametros!$B$10,"MERMA EXCEDE","OK") -> OK
A20: =A8 -> 2026-09 | B20: =B8 -> PT-002 | C20: =Catalogos!I7 -> MP-002 | D20: =C8 -> 70000 | E20: =Catalogos!J7 -> 0.085 | F20: =D20*E20 -> 5950 | G20: =D8 -> 0.058 | H20: =F20*G20 -> 345.1 | I20: =F20+H20 -> 6295.1 | J20: =IF(G20>Parametros!$B$10,"MERMA EXCEDE","OK") -> MERMA EXCEDE
A21: =A8 -> 2026-09 | B21: =B8 -> PT-002 | C21: =Catalogos!I8 -> MP-003 | D21: =C8 -> 70000 | E21: =Catalogos!J8 -> 0.0017 | F21: =D21*E21 -> 119 | G21: =D8 -> 0.058 | H21: =F21*G21 -> 6.902 | I21: =F21+H21 -> 125.902 | J21: =IF(G21>Parametros!$B$10,"MERMA EXCEDE","OK") -> MERMA EXCEDE

Sheet Salidas
A1: Salidas de material: retornos, destrucciones y cambios de régimen (Anexo 24, apdo. A, fr. II inc. c)
A2: Se suman al consumo para calcular la descarga PEPS. Las claves de pedimento son ilustrativas (validar en el Apéndice 2 del Anexo 22).
A4: Pedimento (aduana-patente-número) | B4: Clave | C4: Fecha | D4: Material | E4: Tipo | F4: Cantidad (kg) | G4: Observación
A5: 240-3210-6000412 | B5: RT | C5: 46293 | D5: MP-001 | E5: Retorno | F5: 500 | G5: Retorno de resina sobrante
A6: 240-3210-6000433 | B6: DE | C6: 46295 | D6: MP-002 | E6: Destrucción | F6: 150 | G6: Desperdicio destruido (requiere aviso previo de destrucción; ver LEEME)
A7: 240-3210-6000458 | B7: RT | C7: 46300 | D7: MP-003 | E7: Retorno | F7: 2500 | G7: Retorno de masterbatch: excede lo importado, genera faltante

Sheet Tablero
A1: Tablero de exposición — Control de inventarios Anexo 24 (IMMEX)
A2: =Parametros!B4 -> Plásticos Ejemplo, S.A. de C.V. | C2: Fecha de corte: | D2: =Parametros!$B$8 -> 46315
A4: Valor total del saldo (MXN) | C4: En riesgo dentro de alertas (MXN) | E4: Pedimentos con alerta | G4: Faltante por conciliar (kg)
A5: =SUM(Entradas!$N$5:$N$40) -> 1592905.8 | C5: =SUMIFS(Entradas!$N$5:$N$40,Entradas!$L$5:$L$40,"<="&Parametros!$B$11,Entradas!$J$5:$J$40,">0.001") -> 425185.83 | E5: =COUNTIFS(Entradas!$L$5:$L$40,"<="&Parametros!$B$11,Entradas!$J$5:$J$40,">0.001") -> 3 | G5: =SUM(F17:F19) -> 332.796
A7: Saldo y valor en riesgo por ventana de vencimiento
A8: Ventana | B8: Pedimentos con saldo | C8: Saldo (kg) | D8: Valor en riesgo (MXN) | E8: Nivel
A9: Vencido | B9: =COUNTIFS(Entradas!$L$5:$L$40,"<0",Entradas!$J$5:$J$40,">0.001") -> 0 | C9: =SUMIFS(Entradas!$J$5:$J$40,Entradas!$L$5:$L$40,"<0",Entradas!$J$5:$J$40,">0.001") -> 0 | D9: =SUMIFS(Entradas!$N$5:$N$40,Entradas!$L$5:$L$40,"<0",Entradas!$J$5:$J$40,">0.001") -> 0 | E9: VENCIDO
A10: ="0 a "&Parametros!$B$13&" días" -> 0 a 30 días | B10: =COUNTIFS(Entradas!$L$5:$L$40,">=0",Entradas!$L$5:$L$40,"<="&Parametros!$B$13,Entradas!$J$5:$J$40,">0.001") -> 1 | C10: =SUMIFS(Entradas!$J$5:$J$40,Entradas!$L$5:$L$40,">=0",Entradas!$L$5:$L$40,"<="&Parametros!$B$13,Entradas!$J$5:$J$40,">0.001") -> 827.4 | D10: =SUMIFS(Entradas!$N$5:$N$40,Entradas!$L$5:$L$40,">=0",Entradas!$L$5:$L$40,"<="&Parametros!$B$13,Entradas!$J$5:$J$40,">0.001") -> 28317.765 | E10: ALERTA 30
A11: =(Parametros!$B$13+1)&" a "&Parametros!$B$12&" días" -> 31 a 60 días | B11: =COUNTIFS(Entradas!$L$5:$L$40,">"&Parametros!$B$13,Entradas!$L$5:$L$40,"<="&Parametros!$B$12,Entradas!$J$5:$J$40,">0.001") -> 1 | C11: =SUMIFS(Entradas!$J$5:$J$40,Entradas!$L$5:$L$40,">"&Parametros!$B$13,Entradas!$L$5:$L$40,"<="&Parametros!$B$12,Entradas!$J$5:$J$40,">0.001") -> 557.28 | D11: =SUMIFS(Entradas!$N$5:$N$40,Entradas!$L$5:$L$40,">"&Parametros!$B$13,Entradas!$L$5:$L$40,"<="&Parametros!$B$12,Entradas!$J$5:$J$40,">0.001") -> 13918.068 | E11: ALERTA 60
A12: =(Parametros!$B$12+1)&" a "&Parametros!$B$11&" días" -> 61 a 90 días | B12: =COUNTIFS(Entradas!$L$5:$L$40,">"&Parametros!$B$12,Entradas!$L$5:$L$40,"<="&Parametros!$B$11,Entradas!$J$5:$J$40,">0.001") -> 1 | C12: =SUMIFS(Entradas!$J$5:$J$40,Entradas!$L$5:$L$40,">"&Parametros!$B$12,Entradas!$L$5:$L$40,"<="&Parametros!$B$11,Entradas!$J$5:$J$40,">0.001") -> 15000 | D12: =SUMIFS(Entradas!$N$5:$N$40,Entradas!$L$5:$L$40,">"&Parametros!$B$12,Entradas!$L$5:$L$40,"<="&Parametros!$B$11,Entradas!$J$5:$J$40,">0.001") -> 382950 | E12: ALERTA 90
A13: ="Más de "&Parametros!$B$11&" días" -> Más de 90 días | B13: =COUNTIFS(Entradas!$L$5:$L$40,">"&Parametros!$B$11,Entradas!$J$5:$J$40,">0.001") -> 4 | C13: =SUMIFS(Entradas!$J$5:$J$40,Entradas!$L$5:$L$40,">"&Parametros!$B$11,Entradas!$J$5:$J$40,">0.001") -> 39000 | D13: =SUMIFS(Entradas!$N$5:$N$40,Entradas!$L$5:$L$40,">"&Parametros!$B$11,Entradas!$J$5:$J$40,">0.001") -> 1167720 | E13: OK
A14: Total | B14: =SUM(B9:B13) -> 7 | C14: =SUM(C9:C13) -> 55384.68 | D14: =SUM(D9:D13) -> 1592905.8
A15: Conciliación por material: lo importado contra lo que se debe descargar
A16: Material | B16: Importado (kg) | C16: Descarga requerida (kg) | D16: Descargado PEPS (kg) | E16: Saldo (kg) | F16: Faltante (kg) | G16: Estatus
A17: =Catalogos!A5 -> MP-001 | B17: =SUMIFS(Entradas!$G$5:$G$40,Entradas!$D$5:$D$40,A17) -> 61500 | C17: =SUMIFS(Consumo!$I$14:$I$40,Consumo!$C$14:$C$40,A17)+SUMIFS(Salidas!$F$5:$F$40,Salidas!$D$5:$D$40,A17) -> 23942.72 | D17: =SUMIFS(Entradas!$I$5:$I$40,Entradas!$D$5:$D$40,A17) -> 23942.72 | E17: =B17-D17 -> 37557.28 | F17: =C17-D17 -> 0 | G17: =IF(F17>0.001,"FALTANTE: salidas y consumo exceden lo importado","OK") -> OK
A18: =Catalogos!A6 -> MP-002 | B18: =SUMIFS(Entradas!$G$5:$G$40,Entradas!$D$5:$D$40,A18) -> 29500 | C18: =SUMIFS(Consumo!$I$14:$I$40,Consumo!$C$14:$C$40,A18)+SUMIFS(Salidas!$F$5:$F$40,Salidas!$D$5:$D$40,A18) -> 11672.6 | D18: =SUMIFS(Entradas!$I$5:$I$40,Entradas!$D$5:$D$40,A18) -> 11672.6 | E18: =B18-D18 -> 17827.4 | F18: =C18-D18 -> 0 | G18: =IF(F18>0.001,"FALTANTE: salidas y consumo exceden lo importado","OK") -> OK
A19: =Catalogos!A7 -> MP-003 | B19: =SUMIFS(Entradas!$G$5:$G$40,Entradas!$D$5:$D$40,A19) -> 2900 | C19: =SUMIFS(Consumo!$I$14:$I$40,Consumo!$C$14:$C$40,A19)+SUMIFS(Salidas!$F$5:$F$40,Salidas!$D$5:$D$40,A19) -> 3232.796 | D19: =SUMIFS(Entradas!$I$5:$I$40,Entradas!$D$5:$D$40,A19) -> 2900 | E19: =B19-D19 -> 0 | F19: =C19-D19 -> 332.796 | G19: =IF(F19>0.001,"FALTANTE: salidas y consumo exceden lo importado","OK") -> FALTANTE: salidas y consumo exceden lo importado
A21: Merma por material contra la tolerancia interna
A22: Material | B22: Consumo teórico (kg) | C22: Merma (kg) | D22: Merma % | E22: Tolerancia | F22: Estatus
A23: =Catalogos!A5 -> MP-001 | B23: =SUMIFS(Consumo!$F$14:$F$40,Consumo!$C$14:$C$40,A23) -> 22960 | C23: =SUMIFS(Consumo!$H$14:$H$40,Consumo!$C$14:$C$40,A23) -> 482.72 | D23: =IF(B23=0,0,C23/B23) -> 0.02102439 | E23: =Parametros!$B$10 -> 0.03 | F23: =IF(D23>E23,"MERMA EXCEDE","OK") -> OK
A24: =Catalogos!A6 -> MP-002 | B24: =SUMIFS(Consumo!$F$14:$F$40,Consumo!$C$14:$C$40,A24) -> 11050 | C24: =SUMIFS(Consumo!$H$14:$H$40,Consumo!$C$14:$C$40,A24) -> 472.6 | D24: =IF(B24=0,0,C24/B24) -> 0.042769231 | E24: =Parametros!$B$10 -> 0.03 | F24: =IF(D24>E24,"MERMA EXCEDE","OK") -> MERMA EXCEDE
A25: =Catalogos!A7 -> MP-003 | B25: =SUMIFS(Consumo!$F$14:$F$40,Consumo!$C$14:$C$40,A25) -> 713 | C25: =SUMIFS(Consumo!$H$14:$H$40,Consumo!$C$14:$C$40,A25) -> 19.796 | D25: =IF(B25=0,0,C25/B25) -> 0.027764376 | E25: =Parametros!$B$10 -> 0.03 | F25: =IF(D25>E25,"MERMA EXCEDE","OK") -> OK
A27: Referencia legal (no es un cálculo de exposición)
A28: Multa por no llevar control de inventarios (LA art. 185-B), por infracción: | E28: =Parametros!$B$14 -> 27070 | F28: =Parametros!$B$15 -> 54180
A29: Un material vencido sin retornar ni cambiar de régimen se considera ilegalmente en el país (LA art. 108); sus contribuciones e infracciones no están modeladas aquí.

Sheet Reportes
A1: Reportes mínimos del Anexo 24, apartado A, fracción III
A2: =Parametros!B4 -> Plásticos Ejemplo, S.A. de C.V.
A3: ="RFC: "&Parametros!B5&" | Programa IMMEX: "&Parametros!B6 -> RFC: PEJ210101AB1 | Programa IMMEX: 0000-2024
A4: Fecha de corte: | B4: =Parametros!$B$8 -> 46315
A6: a) Reporte de entrada de mercancías de importación temporal
A7: Pedimento (aduana-patente-número) | B7: Clave | C7: Fecha de entrada | D7: Fracción | E7: Material | F7: Cantidad (kg)
A8: =IF(Entradas!A5="","",Entradas!A5) -> 240-3210-6000101 | B8: =IF(Entradas!A5="","",Entradas!B5) -> IN | C8: =IF(Entradas!A5="","",Entradas!C5) -> 45806 | D8: =IF(Entradas!A5="","",Entradas!F5) -> 3902.10.01 | E8: =IF(Entradas!A5="","",Entradas!D5) -> MP-001 | F8: =IF(Entradas!A5="","",Entradas!G5) -> 24500
A9: =IF(Entradas!A6="","",Entradas!A6) -> 240-3210-6000140 | B9: =IF(Entradas!A6="","",Entradas!B6) -> IN | C9: =IF(Entradas!A6="","",Entradas!C6) -> 45846 | D9: =IF(Entradas!A6="","",Entradas!F6) -> 3902.10.01 | E9: =IF(Entradas!A6="","",Entradas!D6) -> MP-001 | F9: =IF(Entradas!A6="","",Entradas!G6) -> 15000
A10: =IF(Entradas!A7="","",Entradas!A7) -> 240-3210-6000377 | B10: =IF(Entradas!A7="","",Entradas!B7) -> IN | C10: =IF(Entradas!A7="","",Entradas!C7) -> 46091 | D10: =IF(Entradas!A7="","",Entradas!F7) -> 3902.10.01 | E10: =IF(Entradas!A7="","",Entradas!D7) -> MP-001 | F10: =IF(Entradas!A7="","",Entradas!G7) -> 10000
A11: =IF(Entradas!A8="","",Entradas!A8) -> 240-3210-6000590 | B11: =IF(Entradas!A8="","",Entradas!B8) -> IN | C11: =IF(Entradas!A8="","",Entradas!C8) -> 46254 | D11: =IF(Entradas!A8="","",Entradas!F8) -> 3902.10.01 | E11: =IF(Entradas!A8="","",Entradas!D8) -> MP-001 | F11: =IF(Entradas!A8="","",Entradas!G8) -> 12000
A12: =IF(Entradas!A9="","",Entradas!A9) -> 240-3210-6000088 | B12: =IF(Entradas!A9="","",Entradas!B9) -> IN | C12: =IF(Entradas!A9="","",Entradas!C9) -> 45782 | D12: =IF(Entradas!A9="","",Entradas!F9) -> 3903.30.01 | E12: =IF(Entradas!A9="","",Entradas!D9) -> MP-002 | F12: =IF(Entradas!A9="","",Entradas!G9) -> 12500
A13: =IF(Entradas!A10="","",Entradas!A10) -> 240-3210-6000301 | B13: =IF(Entradas!A10="","",Entradas!B10) -> IN | C13: =IF(Entradas!A10="","",Entradas!C10) -> 45993 | D13: =IF(Entradas!A10="","",Entradas!F10) -> 3903.30.01 | E13: =IF(Entradas!A10="","",Entradas!D10) -> MP-002 | F13: =IF(Entradas!A10="","",Entradas!G10) -> 9000
A14: =IF(Entradas!A11="","",Entradas!A11) -> 240-3210-6000544 | B14: =IF(Entradas!A11="","",Entradas!B11) -> IN | C14: =IF(Entradas!A11="","",Entradas!C11) -> 46217 | D14: =IF(Entradas!A11="","",Entradas!F11) -> 3903.30.01 | E14: =IF(Entradas!A11="","",Entradas!D11) -> MP-002 | F14: =IF(Entradas!A11="","",Entradas!G11) -> 8000
A15: =IF(Entradas!A12="","",Entradas!A12) -> 240-3210-6000212 | B15: =IF(Entradas!A12="","",Entradas!B12) -> IN | C15: =IF(Entradas!A12="","",Entradas!C12) -> 45910 | D15: =IF(Entradas!A12="","",Entradas!F12) -> 3206.49.99 | E15: =IF(Entradas!A12="","",Entradas!D12) -> MP-003 | F15: =IF(Entradas!A12="","",Entradas!G12) -> 900
A16: =IF(Entradas!A13="","",Entradas!A13) -> 240-3210-6000350 | B16: =IF(Entradas!A13="","",Entradas!B13) -> IN | C16: =IF(Entradas!A13="","",Entradas!C13) -> 46042 | D16: =IF(Entradas!A13="","",Entradas!F13) -> 3206.49.99 | E16: =IF(Entradas!A13="","",Entradas!D13) -> MP-003 | F16: =IF(Entradas!A13="","",Entradas!G13) -> 1200
A17: =IF(Entradas!A14="","",Entradas!A14) -> 240-3210-6000571 | B17: =IF(Entradas!A14="","",Entradas!B14) -> IN | C17: =IF(Entradas!A14="","",Entradas!C14) -> 46266 | D17: =IF(Entradas!A14="","",Entradas!F14) -> 3206.49.99 | E17: =IF(Entradas!A14="","",Entradas!D14) -> MP-003 | F17: =IF(Entradas!A14="","",Entradas!G14) -> 800
A18: =IF(Entradas!A15="","",Entradas!A15) | B18: =IF(Entradas!A15="","",Entradas!B15) | C18: =IF(Entradas!A15="","",Entradas!C15) | D18: =IF(Entradas!A15="","",Entradas!F15) | E18: =IF(Entradas!A15="","",Entradas!D15) | F18: =IF(Entradas!A15="","",Entradas!G15)
A19: =IF(Entradas!A16="","",Entradas!A16) | B19: =IF(Entradas!A16="","",Entradas!B16) | C19: =IF(Entradas!A16="","",Entradas!C16) | D19: =IF(Entradas!A16="","",Entradas!F16) | E19: =IF(Entradas!A16="","",Entradas!D16) | F19: =IF(Entradas!A16="","",Entradas!G16)
A20: Total | F20: =SUM(F8:F19) -> 93900
A22: b) Reporte de salida de mercancías de importación temporal
A23: Pedimento (aduana-patente-número) | B23: Fecha del pedimento | C23: Clave | D23: Material | E23: Tipo | F23: Cantidad (kg)
A24: =IF(Salidas!A5="","",Salidas!A5) -> 240-3210-6000412 | B24: =IF(Salidas!A5="","",Salidas!C5) -> 46293 | C24: =IF(Salidas!A5="","",Salidas!B5) -> RT | D24: =IF(Salidas!A5="","",Salidas!D5) -> MP-001 | E24: =IF(Salidas!A5="","",Salidas!E5) -> Retorno | F24: =IF(Salidas!A5="","",Salidas!F5) -> 500
A25: =IF(Salidas!A6="","",Salidas!A6) -> 240-3210-6000433 | B25: =IF(Salidas!A6="","",Salidas!C6) -> 46295 | C25: =IF(Salidas!A6="","",Salidas!B6) -> DE | D25: =IF(Salidas!A6="","",Salidas!D6) -> MP-002 | E25: =IF(Salidas!A6="","",Salidas!E6) -> Destrucción | F25: =IF(Salidas!A6="","",Salidas!F6) -> 150
A26: =IF(Salidas!A7="","",Salidas!A7) -> 240-3210-6000458 | B26: =IF(Salidas!A7="","",Salidas!C7) -> 46300 | C26: =IF(Salidas!A7="","",Salidas!B7) -> RT | D26: =IF(Salidas!A7="","",Salidas!D7) -> MP-003 | E26: =IF(Salidas!A7="","",Salidas!E7) -> Retorno | F26: =IF(Salidas!A7="","",Salidas!F7) -> 2500
A27: =IF(Salidas!A8="","",Salidas!A8) | B27: =IF(Salidas!A8="","",Salidas!C8) | C27: =IF(Salidas!A8="","",Salidas!B8) | D27: =IF(Salidas!A8="","",Salidas!D8) | E27: =IF(Salidas!A8="","",Salidas!E8) | F27: =IF(Salidas!A8="","",Salidas!F8)
A28: =IF(Salidas!A9="","",Salidas!A9) | B28: =IF(Salidas!A9="","",Salidas!C9) | C28: =IF(Salidas!A9="","",Salidas!B9) | D28: =IF(Salidas!A9="","",Salidas!D9) | E28: =IF(Salidas!A9="","",Salidas!E9) | F28: =IF(Salidas!A9="","",Salidas!F9)
A29: =IF(Salidas!A10="","",Salidas!A10) | B29: =IF(Salidas!A10="","",Salidas!C10) | C29: =IF(Salidas!A10="","",Salidas!B10) | D29: =IF(Salidas!A10="","",Salidas!D10) | E29: =IF(Salidas!A10="","",Salidas!E10) | F29: =IF(Salidas!A10="","",Salidas!F10)
A30: Total | F30: =SUM(F24:F29) -> 3150
A32: c) Reporte de saldos de mercancías de importación temporal (por fracción arancelaria)
A33: Fracción arancelaria | B33: Descripción | C33: Importado (kg) | D33: Descargado (kg) | E33: Saldo (kg)
A34: =Catalogos!C5 -> 3902.10.01 | B34: =Catalogos!B5 -> Resina polipropileno copolímero | C34: =SUMIFS(Entradas!$G$5:$G$40,Entradas!$F$5:$F$40,A34) -> 61500 | D34: =SUMIFS(Entradas!$I$5:$I$40,Entradas!$F$5:$F$40,A34) -> 23942.72 | E34: =C34-D34 -> 37557.28
A35: =Catalogos!C6 -> 3903.30.01 | B35: =Catalogos!B6 -> Resina ABS | C35: =SUMIFS(Entradas!$G$5:$G$40,Entradas!$F$5:$F$40,A35) -> 29500 | D35: =SUMIFS(Entradas!$I$5:$I$40,Entradas!$F$5:$F$40,A35) -> 11672.6 | E35: =C35-D35 -> 17827.4
A36: =Catalogos!C7 -> 3206.49.99 | B36: =Catalogos!B7 -> Masterbatch colorante | C36: =SUMIFS(Entradas!$G$5:$G$40,Entradas!$F$5:$F$40,A36) -> 2900 | D36: =SUMIFS(Entradas!$I$5:$I$40,Entradas!$F$5:$F$40,A36) -> 2900 | E36: =C36-D36 -> 0
A37: Total | C37: =SUM(C34:C36) -> 93900 | D37: =SUM(D34:D36) -> 38515.32 | E37: =SUM(E34:E36) -> 55384.68
A39: d) Reporte de materiales utilizados en la producción
A40: Periodo | B40: Producto | C40: Material | D40: Piezas | E40: Consumo teórico (kg) | F40: Merma (kg) | G40: Consumo real (kg)
A41: =IF(Consumo!A14="","",Consumo!A14) -> 2026-08 | B41: =IF(Consumo!A14="","",Consumo!B14) -> PT-001 | C41: =IF(Consumo!A14="","",Consumo!C14) -> MP-001 | D41: =IF(Consumo!A14="","",Consumo!D14) -> 400000 | E41: =IF(Consumo!A14="","",Consumo!F14) -> 11200 | F41: =IF(Consumo!A14="","",Consumo!H14) -> 224 | G41: =IF(Consumo!A14="","",Consumo!I14) -> 11424
A42: =IF(Consumo!A15="","",Consumo!A15) -> 2026-08 | B42: =IF(Consumo!A15="","",Consumo!B15) -> PT-001 | C42: =IF(Consumo!A15="","",Consumo!C15) -> MP-003 | D42: =IF(Consumo!A15="","",Consumo!D15) -> 400000 | E42: =IF(Consumo!A15="","",Consumo!F15) -> 240 | F42: =IF(Consumo!A15="","",Consumo!H15) -> 4.8 | G42: =IF(Consumo!A15="","",Consumo!I15) -> 244.8
A43: =IF(Consumo!A16="","",Consumo!A16) -> 2026-08 | B43: =IF(Consumo!A16="","",Consumo!B16) -> PT-002 | C43: =IF(Consumo!A16="","",Consumo!C16) -> MP-002 | D43: =IF(Consumo!A16="","",Consumo!D16) -> 60000 | E43: =IF(Consumo!A16="","",Consumo!F16) -> 5100 | F43: =IF(Consumo!A16="","",Consumo!H16) -> 127.5 | G43: =IF(Consumo!A16="","",Consumo!I16) -> 5227.5
A44: =IF(Consumo!A17="","",Consumo!A17) -> 2026-08 | B44: =IF(Consumo!A17="","",Consumo!B17) -> PT-002 | C44: =IF(Consumo!A17="","",Consumo!C17) -> MP-003 | D44: =IF(Consumo!A17="","",Consumo!D17) -> 60000 | E44: =IF(Consumo!A17="","",Consumo!F17) -> 102 | F44: =IF(Consumo!A17="","",Consumo!H17) -> 2.55 | G44: =IF(Consumo!A17="","",Consumo!I17) -> 104.55
...

Sheet Modelo_Datos
A1: Modelo de datos y reglas para programadores (Java / Python)
A2: Este Excel es la representación del sistema. Cada hoja de captura es una tabla; cada columna de fórmula es una regla de negocio.
A4: Tabla | B4: Campo | C4: Tipo | D4: Regla / origen
A5: material | B5: clave, descripcion, fraccion, um_tigie, plazo_meses | C5: texto / int | D5: Catálogo. plazo_meses viene de LA art. 108 (18 meses para insumos).
A6: producto | B6: clave, descripcion, fraccion, um_tigie | C6: texto | D6: Catálogo.
A7: bom | B7: producto, material, kg_por_pieza | C7: decimal | D7: Lista de materiales. Consumo teórico = piezas × kg_por_pieza.
A8: pedimento_entrada (lote) | B8: pedimento, clave, fecha_entrada, material, cantidad, valor_unit_usd | C8: — | D8: Un renglón por pedimento y material. Es la unidad que se descarga por PEPS y la que tiene reloj legal.
A9: produccion | B9: periodo, producto, piezas, merma_pct | C9: — | D9: Captura mensual del cliente.
A10: consumo (derivada) | B10: periodo, producto, material, consumo_teorico, merma_kg, consumo_real | C10: — | D10: consumo_real = piezas × kg_por_pieza × (1 + merma_pct). Se calcula, no se captura.
A11: salida | B11: pedimento, clave, fecha, material, tipo, cantidad | C11: — | D11: Retorno, destrucción, transferencia o cambio de régimen. Descarga igual que el consumo.
A12: parametro | B12: ver hoja Parametros | C12: — | D12: Distinguir LEY / RETO / SUPUESTO. Todo parámetro debe poder editarse sin tocar el código.
A14: Algoritmo PEPS (primero en entrar, primero en salir) — Anexo 24, apdo. A, fr. II inc. c)
A15: para cada material m:
A16: por_descargar = suma(consumo_real de m) + suma(salidas de m)
A17: para cada lote de m ordenado por fecha_entrada ascendente (desempate: número de pedimento):
A18: descargado = min(lote.cantidad, por_descargar)
A19: lote.saldo = lote.cantidad − descargado ; por_descargar −= descargado
A20: si por_descargar > 0 → EXCEPCIÓN 'faltante' (salidas y consumo exceden lo importado)
A21: vence = fecha_entrada + plazo_meses del material dias_restantes = vence − fecha_corte
A22: alerta = VENCIDO si <0 ; ALERTA 30 / 60 / 90 según dias_restantes ; Agotado si saldo = 0
A23: riesgo_mxn = saldo × valor_unit_usd × tipo_cambio
A25: En el sistema real: NO sobrescribir. Registrar cada descarga como un movimiento inmutable (quién, cuándo, por qué, pedimento afectado, cantidad) y
A26: calcular saldos como suma de movimientos. Así se cumple 'cada cambio queda registrado' y se puede simular y revertir descargas.
A29: Casos de prueba (oráculo): con los datos de este libro, el programa debe dar estos descargos por pedimento
A30: Pedimento | B30: Descargado esperado (kg) | C30: Descargado en el Excel (kg) | D30: ¿Coincide?
A31: =Entradas!A5 -> 240-3210-6000101 | B31: 23942.72 | C31: =Entradas!I5 -> 23942.72 | D31: =IF(ABS(B31-C31)<0.01,"OK","REVISAR") -> OK
A32: =Entradas!A6 -> 240-3210-6000140 | B32: 0 | C32: =Entradas!I6 -> 0 | D32: =IF(ABS(B32-C32)<0.01,"OK","REVISAR") -> OK
A33: =Entradas!A7 -> 240-3210-6000377 | B33: 0 | C33: =Entradas!I7 -> 0 | D33: =IF(ABS(B33-C33)<0.01,"OK","REVISAR") -> OK
A34: =Entradas!A8 -> 240-3210-6000590 | B34: 0 | C34: =Entradas!I8 -> 0 | D34: =IF(ABS(B34-C34)<0.01,"OK","REVISAR") -> OK
A35: =Entradas!A9 -> 240-3210-6000088 | B35: 11672.6 | C35: =Entradas!I9 -> 11672.6 | D35: =IF(ABS(B35-C35)<0.01,"OK","REVISAR") -> OK
A36: =Entradas!A10 -> 240-3210-6000301 | B36: 0 | C36: =Entradas!I10 -> 0 | D36: =IF(ABS(B36-C36)<0.01,"OK","REVISAR") -> OK
A37: =Entradas!A11 -> 240-3210-6000544 | B37: 0 | C37: =Entradas!I11 -> 0 | D37: =IF(ABS(B37-C37)<0.01,"OK","REVISAR") -> OK
A38: =Entradas!A12 -> 240-3210-6000212 | B38: 900 | C38: =Entradas!I12 -> 900 | D38: =IF(ABS(B38-C38)<0.01,"OK","REVISAR") -> OK
A39: =Entradas!A13 -> 240-3210-6000350 | B39: 1200 | C39: =Entradas!I13 -> 1200 | D39: =IF(ABS(B39-C39)<0.01,"OK","REVISAR") -> OK
A40: =Entradas!A14 -> 240-3210-6000571 | B40: 800 | C40: =Entradas!I14 -> 800 | D40: =IF(ABS(B40-C40)<0.01,"OK","REVISAR") -> OK
A41: Faltante esperado de MP-003 (masterbatch): 332.80 kg. Fecha de corte 20/10/2026; si cambia la fecha, cambian días y alertas, no los descargos.
